Iniciando proceso... 
Traceback (most recent call last):
  File "C:\_Tmp\Python\saf\manage.py", line 22, in <module>
    main()
    ~~~~^^
  File "C:\_Tmp\Python\saf\manage.py", line 18, in main
    execute_from_command_line(sys.argv)
    ~~~~~~~~~~~~~~~~~~~~~~~~~^^^^^^^^^^
  File "C:\Users\Administrador\AppData\Local\Programs\Python\Python313\Lib\site-packages\django\core\management\__init__.py", line 442, in execute_from_command_line
    utility.execute()
    ~~~~~~~~~~~~~~~^^
  File "C:\Users\Administrador\AppData\Local\Programs\Python\Python313\Lib\site-packages\django\core\management\__init__.py", line 382, in execute
    settings.INSTALLED_APPS
  File "C:\Users\Administrador\AppData\Local\Programs\Python\Python313\Lib\site-packages\django\conf\__init__.py", line 81, in __getattr__
    self._setup(name)
    ~~~~~~~~~~~^^^^^^
  File "C:\Users\Administrador\AppData\Local\Programs\Python\Python313\Lib\site-packages\django\conf\__init__.py", line 68, in _setup
    self._wrapped = Settings(settings_module)
                    ~~~~~~~~^^^^^^^^^^^^^^^^^
  File "C:\Users\Administrador\AppData\Local\Programs\Python\Python313\Lib\site-packages\django\conf\__init__.py", line 166, in __init__
    mod = importlib.import_module(self.SETTINGS_MODULE)
  File "C:\Users\Administrador\AppData\Local\Programs\Python\Python313\Lib\importlib\__init__.py", line 88, in import_module
    return _bootstrap._gcd_import(name[level:], package, level)
           ~~~~~~~~~~~~~~~~~~~~~~^^^^^^^^^^^^^^^^^^^^^^^^^^^^^^
  File "<frozen importlib._bootstrap>", line 1387, in _gcd_import
  File "<frozen importlib._bootstrap>", line 1360, in _find_and_load
  File "<frozen importlib._bootstrap>", line 1331, in _find_and_load_unlocked
  File "<frozen importlib._bootstrap>", line 935, in _load_unlocked
  File "<frozen importlib._bootstrap_external>", line 1022, in exec_module
  File "<frozen importlib._bootstrap_external>", line 1160, in get_code
  File "<frozen importlib._bootstrap_external>", line 1090, in source_to_code
  File "<frozen importlib._bootstrap>", line 488, in _call_with_frames_removed
  File "C:\_Tmp\Python\saf\saf\settings.py", line 1
    from pathlib import Path
IndentationError: unexpected indent
Traceback (most recent call last):
  File "C:\_Tmp\Python\saf\manage.py", line 22, in <module>
    main()
    ~~~~^^
  File "C:\_Tmp\Python\saf\manage.py", line 18, in main
    execute_from_command_line(sys.argv)
    ~~~~~~~~~~~~~~~~~~~~~~~~~^^^^^^^^^^
  File "C:\Users\Administrador\AppData\Local\Programs\Python\Python313\Lib\site-packages\django\core\management\__init__.py", line 442, in execute_from_command_line
    utility.execute()
    ~~~~~~~~~~~~~~~^^
  File "C:\Users\Administrador\AppData\Local\Programs\Python\Python313\Lib\site-packages\django\core\management\__init__.py", line 382, in execute
    settings.INSTALLED_APPS
  File "C:\Users\Administrador\AppData\Local\Programs\Python\Python313\Lib\site-packages\django\conf\__init__.py", line 81, in __getattr__
    self._setup(name)
    ~~~~~~~~~~~^^^^^^
  File "C:\Users\Administrador\AppData\Local\Programs\Python\Python313\Lib\site-packages\django\conf\__init__.py", line 68, in _setup
    self._wrapped = Settings(settings_module)
                    ~~~~~~~~^^^^^^^^^^^^^^^^^
  File "C:\Users\Administrador\AppData\Local\Programs\Python\Python313\Lib\site-packages\django\conf\__init__.py", line 166, in __init__
    mod = importlib.import_module(self.SETTINGS_MODULE)
  File "C:\Users\Administrador\AppData\Local\Programs\Python\Python313\Lib\importlib\__init__.py", line 88, in import_module
    return _bootstrap._gcd_import(name[level:], package, level)
           ~~~~~~~~~~~~~~~~~~~~~~^^^^^^^^^^^^^^^^^^^^^^^^^^^^^^
  File "<frozen importlib._bootstrap>", line 1387, in _gcd_import
  File "<frozen importlib._bootstrap>", line 1360, in _find_and_load
  File "<frozen importlib._bootstrap>", line 1331, in _find_and_load_unlocked
  File "<frozen importlib._bootstrap>", line 935, in _load_unlocked
  File "<frozen importlib._bootstrap_external>", line 1022, in exec_module
  File "<frozen importlib._bootstrap_external>", line 1160, in get_code
  File "<frozen importlib._bootstrap_external>", line 1090, in source_to_code
  File "<frozen importlib._bootstrap>", line 488, in _call_with_frames_removed
  File "C:\_Tmp\Python\saf\saf\settings.py", line 1
    from pathlib import Path
IndentationError: unexpected indent
Traceback (most recent call last):
  File "C:\_Tmp\Python\saf\manage.py", line 22, in <module>
    main()
    ~~~~^^
  File "C:\_Tmp\Python\saf\manage.py", line 18, in main
    execute_from_command_line(sys.argv)
    ~~~~~~~~~~~~~~~~~~~~~~~~~^^^^^^^^^^
  File "C:\Users\Administrador\AppData\Local\Programs\Python\Python313\Lib\site-packages\django\core\management\__init__.py", line 442, in execute_from_command_line
    utility.execute()
    ~~~~~~~~~~~~~~~^^
  File "C:\Users\Administrador\AppData\Local\Programs\Python\Python313\Lib\site-packages\django\core\management\__init__.py", line 382, in execute
    settings.INSTALLED_APPS
  File "C:\Users\Administrador\AppData\Local\Programs\Python\Python313\Lib\site-packages\django\conf\__init__.py", line 81, in __getattr__
    self._setup(name)
    ~~~~~~~~~~~^^^^^^
  File "C:\Users\Administrador\AppData\Local\Programs\Python\Python313\Lib\site-packages\django\conf\__init__.py", line 68, in _setup
    self._wrapped = Settings(settings_module)
                    ~~~~~~~~^^^^^^^^^^^^^^^^^
  File "C:\Users\Administrador\AppData\Local\Programs\Python\Python313\Lib\site-packages\django\conf\__init__.py", line 166, in __init__
    mod = importlib.import_module(self.SETTINGS_MODULE)
  File "C:\Users\Administrador\AppData\Local\Programs\Python\Python313\Lib\importlib\__init__.py", line 88, in import_module
    return _bootstrap._gcd_import(name[level:], package, level)
           ~~~~~~~~~~~~~~~~~~~~~~^^^^^^^^^^^^^^^^^^^^^^^^^^^^^^
  File "<frozen importlib._bootstrap>", line 1387, in _gcd_import
  File "<frozen importlib._bootstrap>", line 1360, in _find_and_load
  File "<frozen importlib._bootstrap>", line 1331, in _find_and_load_unlocked
  File "<frozen importlib._bootstrap>", line 935, in _load_unlocked
  File "<frozen importlib._bootstrap_external>", line 1022, in exec_module
  File "<frozen importlib._bootstrap_external>", line 1160, in get_code
  File "<frozen importlib._bootstrap_external>", line 1090, in source_to_code
  File "<frozen importlib._bootstrap>", line 488, in _call_with_frames_removed
  File "C:\_Tmp\Python\saf\saf\settings.py", line 1
    from pathlib import Path
IndentationError: unexpected indent
Proceso finalizado. 
