Iniciando proceso... 
Traceback (most recent call last):
  File "C:\_Tmp\Python\saf\manage.py", line 22, in <module>
    main()
    ~~~~^^
  File "C:\_Tmp\Python\saf\manage.py", line 18, in main
    execute_from_command_line(sys.argv)
    ~~~~~~~~~~~~~~~~~~~~~~~~~^^^^^^^^^^
  File "C:\Users\Administrador\AppData\Local\Programs\Python\Python313\Lib\site-packages\django\core\management\__init__.py", line 442, in execute_from_command_line
    utility.execute()
    ~~~~~~~~~~~~~~~^^
  File "C:\Users\Administrador\AppData\Local\Programs\Python\Python313\Lib\site-packages\django\core\management\__init__.py", line 436, in execute
    self.fetch_command(subcommand).run_from_argv(self.argv)
    ~~~~~~~~~~~~~~~~~~~~~~~~~~~~~~~~~~~~~~~~~~~~^^^^^^^^^^^
  File "C:\Users\Administrador\AppData\Local\Programs\Python\Python313\Lib\site-packages\django\core\management\base.py", line 413, in run_from_argv
    self.execute(*args, **cmd_options)
    ~~~~~~~~~~~~^^^^^^^^^^^^^^^^^^^^^^
  File "C:\Users\Administrador\AppData\Local\Programs\Python\Python313\Lib\site-packages\django\core\management\base.py", line 454, in execute
    self.check()
    ~~~~~~~~~~^^
  File "C:\Users\Administrador\AppData\Local\Programs\Python\Python313\Lib\site-packages\django\core\management\base.py", line 486, in check
    all_issues = checks.run_checks(
        app_configs=app_configs,
    ...<2 lines>...
        databases=databases,
    )
  File "C:\Users\Administrador\AppData\Local\Programs\Python\Python313\Lib\site-packages\django\core\checks\registry.py", line 88, in run_checks
    new_errors = check(app_configs=app_configs, databases=databases)
  File "C:\Users\Administrador\AppData\Local\Programs\Python\Python313\Lib\site-packages\django\core\checks\urls.py", line 16, in check_url_config
    return check_resolver(resolver)
  File "C:\Users\Administrador\AppData\Local\Programs\Python\Python313\Lib\site-packages\django\core\checks\urls.py", line 26, in check_resolver
    return check_method()
  File "C:\Users\Administrador\AppData\Local\Programs\Python\Python313\Lib\site-packages\django\urls\resolvers.py", line 531, in check
    for pattern in self.url_patterns:
                   ^^^^^^^^^^^^^^^^^
  File "C:\Users\Administrador\AppData\Local\Programs\Python\Python313\Lib\site-packages\django\utils\functional.py", line 47, in __get__
    res = instance.__dict__[self.name] = self.func(instance)
                                         ~~~~~~~~~^^^^^^^^^^
  File "C:\Users\Administrador\AppData\Local\Programs\Python\Python313\Lib\site-packages\django\urls\resolvers.py", line 718, in url_patterns
    patterns = getattr(self.urlconf_module, "urlpatterns", self.urlconf_module)
                       ^^^^^^^^^^^^^^^^^^^
  File "C:\Users\Administrador\AppData\Local\Programs\Python\Python313\Lib\site-packages\django\utils\functional.py", line 47, in __get__
    res = instance.__dict__[self.name] = self.func(instance)
                                         ~~~~~~~~~^^^^^^^^^^
  File "C:\Users\Administrador\AppData\Local\Programs\Python\Python313\Lib\site-packages\django\urls\resolvers.py", line 711, in urlconf_module
    return import_module(self.urlconf_name)
  File "C:\Users\Administrador\AppData\Local\Programs\Python\Python313\Lib\importlib\__init__.py", line 88, in import_module
    return _bootstrap._gcd_import(name[level:], package, level)
           ~~~~~~~~~~~~~~~~~~~~~~^^^^^^^^^^^^^^^^^^^^^^^^^^^^^^
  File "<frozen importlib._bootstrap>", line 1387, in _gcd_import
  File "<frozen importlib._bootstrap>", line 1360, in _find_and_load
  File "<frozen importlib._bootstrap>", line 1331, in _find_and_load_unlocked
  File "<frozen importlib._bootstrap>", line 935, in _load_unlocked
  File "<frozen importlib._bootstrap_external>", line 1026, in exec_module
  File "<frozen importlib._bootstrap>", line 488, in _call_with_frames_removed
  File "C:\_Tmp\Python\saf\saf\urls.py", line 26, in <module>
    path('articulos/', include('articulos.urls')),
                       ~~~~~~~^^^^^^^^^^^^^^^^^^
  File "C:\Users\Administrador\AppData\Local\Programs\Python\Python313\Lib\site-packages\django\urls\conf.py", line 39, in include
    urlconf_module = import_module(urlconf_module)
  File "C:\Users\Administrador\AppData\Local\Programs\Python\Python313\Lib\importlib\__init__.py", line 88, in import_module
    return _bootstrap._gcd_import(name[level:], package, level)
           ~~~~~~~~~~~~~~~~~~~~~~^^^^^^^^^^^^^^^^^^^^^^^^^^^^^^
  File "<frozen importlib._bootstrap>", line 1387, in _gcd_import
  File "<frozen importlib._bootstrap>", line 1360, in _find_and_load
  File "<frozen importlib._bootstrap>", line 1331, in _find_and_load_unlocked
  File "<frozen importlib._bootstrap>", line 935, in _load_unlocked
  File "<frozen importlib._bootstrap_external>", line 1026, in exec_module
  File "<frozen importlib._bootstrap>", line 488, in _call_with_frames_removed
  File "C:\_Tmp\Python\saf\articulos\urls.py", line 3, in <module>
    from .views import agregar_parametro, listar_parametros, prueba_formulario
ImportError: cannot import name 'prueba_formulario' from 'articulos.views' (C:\_Tmp\Python\saf\articulos\views.py)
Traceback (most recent call last):
  File "C:\_Tmp\Python\saf\manage.py", line 22, in <module>
    main()
    ~~~~^^
  File "C:\_Tmp\Python\saf\manage.py", line 18, in main
    execute_from_command_line(sys.argv)
    ~~~~~~~~~~~~~~~~~~~~~~~~~^^^^^^^^^^
  File "C:\Users\Administrador\AppData\Local\Programs\Python\Python313\Lib\site-packages\django\core\management\__init__.py", line 442, in execute_from_command_line
    utility.execute()
    ~~~~~~~~~~~~~~~^^
  File "C:\Users\Administrador\AppData\Local\Programs\Python\Python313\Lib\site-packages\django\core\management\__init__.py", line 436, in execute
    self.fetch_command(subcommand).run_from_argv(self.argv)
    ~~~~~~~~~~~~~~~~~~~~~~~~~~~~~~~~~~~~~~~~~~~~^^^^^^^^^^^
  File "C:\Users\Administrador\AppData\Local\Programs\Python\Python313\Lib\site-packages\django\core\management\base.py", line 413, in run_from_argv
    self.execute(*args, **cmd_options)
    ~~~~~~~~~~~~^^^^^^^^^^^^^^^^^^^^^^
  File "C:\Users\Administrador\AppData\Local\Programs\Python\Python313\Lib\site-packages\django\core\management\base.py", line 459, in execute
    output = self.handle(*args, **options)
  File "C:\Users\Administrador\AppData\Local\Programs\Python\Python313\Lib\site-packages\django\core\management\base.py", line 107, in wrapper
    res = handle_func(*args, **kwargs)
  File "C:\Users\Administrador\AppData\Local\Programs\Python\Python313\Lib\site-packages\django\core\management\commands\migrate.py", line 101, in handle
    self.check(databases=[database])
    ~~~~~~~~~~^^^^^^^^^^^^^^^^^^^^^^
  File "C:\Users\Administrador\AppData\Local\Programs\Python\Python313\Lib\site-packages\django\core\management\base.py", line 486, in check
    all_issues = checks.run_checks(
        app_configs=app_configs,
    ...<2 lines>...
        databases=databases,
    )
  File "C:\Users\Administrador\AppData\Local\Programs\Python\Python313\Lib\site-packages\django\core\checks\registry.py", line 88, in run_checks
    new_errors = check(app_configs=app_configs, databases=databases)
  File "C:\Users\Administrador\AppData\Local\Programs\Python\Python313\Lib\site-packages\django\core\checks\urls.py", line 16, in check_url_config
    return check_resolver(resolver)
  File "C:\Users\Administrador\AppData\Local\Programs\Python\Python313\Lib\site-packages\django\core\checks\urls.py", line 26, in check_resolver
    return check_method()
  File "C:\Users\Administrador\AppData\Local\Programs\Python\Python313\Lib\site-packages\django\urls\resolvers.py", line 531, in check
    for pattern in self.url_patterns:
                   ^^^^^^^^^^^^^^^^^
  File "C:\Users\Administrador\AppData\Local\Programs\Python\Python313\Lib\site-packages\django\utils\functional.py", line 47, in __get__
    res = instance.__dict__[self.name] = self.func(instance)
                                         ~~~~~~~~~^^^^^^^^^^
  File "C:\Users\Administrador\AppData\Local\Programs\Python\Python313\Lib\site-packages\django\urls\resolvers.py", line 718, in url_patterns
    patterns = getattr(self.urlconf_module, "urlpatterns", self.urlconf_module)
                       ^^^^^^^^^^^^^^^^^^^
  File "C:\Users\Administrador\AppData\Local\Programs\Python\Python313\Lib\site-packages\django\utils\functional.py", line 47, in __get__
    res = instance.__dict__[self.name] = self.func(instance)
                                         ~~~~~~~~~^^^^^^^^^^
  File "C:\Users\Administrador\AppData\Local\Programs\Python\Python313\Lib\site-packages\django\urls\resolvers.py", line 711, in urlconf_module
    return import_module(self.urlconf_name)
  File "C:\Users\Administrador\AppData\Local\Programs\Python\Python313\Lib\importlib\__init__.py", line 88, in import_module
    return _bootstrap._gcd_import(name[level:], package, level)
           ~~~~~~~~~~~~~~~~~~~~~~^^^^^^^^^^^^^^^^^^^^^^^^^^^^^^
  File "<frozen importlib._bootstrap>", line 1387, in _gcd_import
  File "<frozen importlib._bootstrap>", line 1360, in _find_and_load
  File "<frozen importlib._bootstrap>", line 1331, in _find_and_load_unlocked
  File "<frozen importlib._bootstrap>", line 935, in _load_unlocked
  File "<frozen importlib._bootstrap_external>", line 1026, in exec_module
  File "<frozen importlib._bootstrap>", line 488, in _call_with_frames_removed
  File "C:\_Tmp\Python\saf\saf\urls.py", line 26, in <module>
    path('articulos/', include('articulos.urls')),
                       ~~~~~~~^^^^^^^^^^^^^^^^^^
  File "C:\Users\Administrador\AppData\Local\Programs\Python\Python313\Lib\site-packages\django\urls\conf.py", line 39, in include
    urlconf_module = import_module(urlconf_module)
  File "C:\Users\Administrador\AppData\Local\Programs\Python\Python313\Lib\importlib\__init__.py", line 88, in import_module
    return _bootstrap._gcd_import(name[level:], package, level)
           ~~~~~~~~~~~~~~~~~~~~~~^^^^^^^^^^^^^^^^^^^^^^^^^^^^^^
  File "<frozen importlib._bootstrap>", line 1387, in _gcd_import
  File "<frozen importlib._bootstrap>", line 1360, in _find_and_load
  File "<frozen importlib._bootstrap>", line 1331, in _find_and_load_unlocked
  File "<frozen importlib._bootstrap>", line 935, in _load_unlocked
  File "<frozen importlib._bootstrap_external>", line 1026, in exec_module
  File "<frozen importlib._bootstrap>", line 488, in _call_with_frames_removed
  File "C:\_Tmp\Python\saf\articulos\urls.py", line 3, in <module>
    from .views import agregar_parametro, listar_parametros, prueba_formulario
ImportError: cannot import name 'prueba_formulario' from 'articulos.views' (C:\_Tmp\Python\saf\articulos\views.py)
Watching for file changes with StatReloader
Exception in thread django-main-thread:
Traceback (most recent call last):
  File "C:\Users\Administrador\AppData\Local\Programs\Python\Python313\Lib\threading.py", line 1043, in _bootstrap_inner
    self.run()
    ~~~~~~~~^^
  File "C:\Users\Administrador\AppData\Local\Programs\Python\Python313\Lib\threading.py", line 994, in run
    self._target(*self._args, **self._kwargs)
    ~~~~~~~~~~~~^^^^^^^^^^^^^^^^^^^^^^^^^^^^^
  File "C:\Users\Administrador\AppData\Local\Programs\Python\Python313\Lib\site-packages\django\utils\autoreload.py", line 64, in wrapper
    fn(*args, **kwargs)
    ~~^^^^^^^^^^^^^^^^^
  File "C:\Users\Administrador\AppData\Local\Programs\Python\Python313\Lib\site-packages\django\core\management\commands\runserver.py", line 134, in inner_run
    self.check(display_num_errors=True)
    ~~~~~~~~~~^^^^^^^^^^^^^^^^^^^^^^^^^
  File "C:\Users\Administrador\AppData\Local\Programs\Python\Python313\Lib\site-packages\django\core\management\base.py", line 486, in check
    all_issues = checks.run_checks(
        app_configs=app_configs,
    ...<2 lines>...
        databases=databases,
    )
  File "C:\Users\Administrador\AppData\Local\Programs\Python\Python313\Lib\site-packages\django\core\checks\registry.py", line 88, in run_checks
    new_errors = check(app_configs=app_configs, databases=databases)
  File "C:\Users\Administrador\AppData\Local\Programs\Python\Python313\Lib\site-packages\django\core\checks\urls.py", line 16, in check_url_config
    return check_resolver(resolver)
  File "C:\Users\Administrador\AppData\Local\Programs\Python\Python313\Lib\site-packages\django\core\checks\urls.py", line 26, in check_resolver
    return check_method()
  File "C:\Users\Administrador\AppData\Local\Programs\Python\Python313\Lib\site-packages\django\urls\resolvers.py", line 531, in check
    for pattern in self.url_patterns:
                   ^^^^^^^^^^^^^^^^^
  File "C:\Users\Administrador\AppData\Local\Programs\Python\Python313\Lib\site-packages\django\utils\functional.py", line 47, in __get__
    res = instance.__dict__[self.name] = self.func(instance)
                                         ~~~~~~~~~^^^^^^^^^^
  File "C:\Users\Administrador\AppData\Local\Programs\Python\Python313\Lib\site-packages\django\urls\resolvers.py", line 718, in url_patterns
    patterns = getattr(self.urlconf_module, "urlpatterns", self.urlconf_module)
                       ^^^^^^^^^^^^^^^^^^^
  File "C:\Users\Administrador\AppData\Local\Programs\Python\Python313\Lib\site-packages\django\utils\functional.py", line 47, in __get__
    res = instance.__dict__[self.name] = self.func(instance)
                                         ~~~~~~~~~^^^^^^^^^^
  File "C:\Users\Administrador\AppData\Local\Programs\Python\Python313\Lib\site-packages\django\urls\resolvers.py", line 711, in urlconf_module
    return import_module(self.urlconf_name)
  File "C:\Users\Administrador\AppData\Local\Programs\Python\Python313\Lib\importlib\__init__.py", line 88, in import_module
    return _bootstrap._gcd_import(name[level:], package, level)
           ~~~~~~~~~~~~~~~~~~~~~~^^^^^^^^^^^^^^^^^^^^^^^^^^^^^^
  File "<frozen importlib._bootstrap>", line 1387, in _gcd_import
  File "<frozen importlib._bootstrap>", line 1360, in _find_and_load
  File "<frozen importlib._bootstrap>", line 1331, in _find_and_load_unlocked
  File "<frozen importlib._bootstrap>", line 935, in _load_unlocked
  File "<frozen importlib._bootstrap_external>", line 1026, in exec_module
  File "<frozen importlib._bootstrap>", line 488, in _call_with_frames_removed
  File "C:\_Tmp\Python\saf\saf\urls.py", line 26, in <module>
    path('articulos/', include('articulos.urls')),
                       ~~~~~~~^^^^^^^^^^^^^^^^^^
  File "C:\Users\Administrador\AppData\Local\Programs\Python\Python313\Lib\site-packages\django\urls\conf.py", line 39, in include
    urlconf_module = import_module(urlconf_module)
  File "C:\Users\Administrador\AppData\Local\Programs\Python\Python313\Lib\importlib\__init__.py", line 88, in import_module
    return _bootstrap._gcd_import(name[level:], package, level)
           ~~~~~~~~~~~~~~~~~~~~~~^^^^^^^^^^^^^^^^^^^^^^^^^^^^^^
  File "<frozen importlib._bootstrap>", line 1387, in _gcd_import
  File "<frozen importlib._bootstrap>", line 1360, in _find_and_load
  File "<frozen importlib._bootstrap>", line 1331, in _find_and_load_unlocked
  File "<frozen importlib._bootstrap>", line 935, in _load_unlocked
  File "<frozen importlib._bootstrap_external>", line 1026, in exec_module
  File "<frozen importlib._bootstrap>", line 488, in _call_with_frames_removed
  File "C:\_Tmp\Python\saf\articulos\urls.py", line 3, in <module>
    from .views import agregar_parametro, listar_parametros, prueba_formulario
ImportError: cannot import name 'prueba_formulario' from 'articulos.views' (C:\_Tmp\Python\saf\articulos\views.py)
C:\_Tmp\Python\saf\articulos\views.py changed, reloading.
Performing system checks...

Watching for file changes with StatReloader
Exception in thread django-main-thread:
Traceback (most recent call last):
  File "C:\Users\Administrador\AppData\Local\Programs\Python\Python313\Lib\threading.py", line 1043, in _bootstrap_inner
    self.run()
    ~~~~~~~~^^
  File "C:\Users\Administrador\AppData\Local\Programs\Python\Python313\Lib\threading.py", line 994, in run
    self._target(*self._args, **self._kwargs)
    ~~~~~~~~~~~~^^^^^^^^^^^^^^^^^^^^^^^^^^^^^
  File "C:\Users\Administrador\AppData\Local\Programs\Python\Python313\Lib\site-packages\django\utils\autoreload.py", line 64, in wrapper
    fn(*args, **kwargs)
    ~~^^^^^^^^^^^^^^^^^
  File "C:\Users\Administrador\AppData\Local\Programs\Python\Python313\Lib\site-packages\django\core\management\commands\runserver.py", line 134, in inner_run
    self.check(display_num_errors=True)
    ~~~~~~~~~~^^^^^^^^^^^^^^^^^^^^^^^^^
  File "C:\Users\Administrador\AppData\Local\Programs\Python\Python313\Lib\site-packages\django\core\management\base.py", line 486, in check
    all_issues = checks.run_checks(
        app_configs=app_configs,
    ...<2 lines>...
        databases=databases,
    )
  File "C:\Users\Administrador\AppData\Local\Programs\Python\Python313\Lib\site-packages\django\core\checks\registry.py", line 88, in run_checks
    new_errors = check(app_configs=app_configs, databases=databases)
  File "C:\Users\Administrador\AppData\Local\Programs\Python\Python313\Lib\site-packages\django\core\checks\urls.py", line 16, in check_url_config
    return check_resolver(resolver)
  File "C:\Users\Administrador\AppData\Local\Programs\Python\Python313\Lib\site-packages\django\core\checks\urls.py", line 26, in check_resolver
    return check_method()
  File "C:\Users\Administrador\AppData\Local\Programs\Python\Python313\Lib\site-packages\django\urls\resolvers.py", line 531, in check
    for pattern in self.url_patterns:
                   ^^^^^^^^^^^^^^^^^
  File "C:\Users\Administrador\AppData\Local\Programs\Python\Python313\Lib\site-packages\django\utils\functional.py", line 47, in __get__
    res = instance.__dict__[self.name] = self.func(instance)
                                         ~~~~~~~~~^^^^^^^^^^
  File "C:\Users\Administrador\AppData\Local\Programs\Python\Python313\Lib\site-packages\django\urls\resolvers.py", line 718, in url_patterns
    patterns = getattr(self.urlconf_module, "urlpatterns", self.urlconf_module)
                       ^^^^^^^^^^^^^^^^^^^
  File "C:\Users\Administrador\AppData\Local\Programs\Python\Python313\Lib\site-packages\django\utils\functional.py", line 47, in __get__
    res = instance.__dict__[self.name] = self.func(instance)
                                         ~~~~~~~~~^^^^^^^^^^
  File "C:\Users\Administrador\AppData\Local\Programs\Python\Python313\Lib\site-packages\django\urls\resolvers.py", line 711, in urlconf_module
    return import_module(self.urlconf_name)
  File "C:\Users\Administrador\AppData\Local\Programs\Python\Python313\Lib\importlib\__init__.py", line 88, in import_module
    return _bootstrap._gcd_import(name[level:], package, level)
           ~~~~~~~~~~~~~~~~~~~~~~^^^^^^^^^^^^^^^^^^^^^^^^^^^^^^
  File "<frozen importlib._bootstrap>", line 1387, in _gcd_import
  File "<frozen importlib._bootstrap>", line 1360, in _find_and_load
  File "<frozen importlib._bootstrap>", line 1331, in _find_and_load_unlocked
  File "<frozen importlib._bootstrap>", line 935, in _load_unlocked
  File "<frozen importlib._bootstrap_external>", line 1026, in exec_module
  File "<frozen importlib._bootstrap>", line 488, in _call_with_frames_removed
  File "C:\_Tmp\Python\saf\saf\urls.py", line 26, in <module>
    path('articulos/', include('articulos.urls')),
                       ~~~~~~~^^^^^^^^^^^^^^^^^^
  File "C:\Users\Administrador\AppData\Local\Programs\Python\Python313\Lib\site-packages\django\urls\conf.py", line 39, in include
    urlconf_module = import_module(urlconf_module)
  File "C:\Users\Administrador\AppData\Local\Programs\Python\Python313\Lib\importlib\__init__.py", line 88, in import_module
    return _bootstrap._gcd_import(name[level:], package, level)
           ~~~~~~~~~~~~~~~~~~~~~~^^^^^^^^^^^^^^^^^^^^^^^^^^^^^^
  File "<frozen importlib._bootstrap>", line 1387, in _gcd_import
  File "<frozen importlib._bootstrap>", line 1360, in _find_and_load
  File "<frozen importlib._bootstrap>", line 1331, in _find_and_load_unlocked
  File "<frozen importlib._bootstrap>", line 935, in _load_unlocked
  File "<frozen importlib._bootstrap_external>", line 1026, in exec_module
  File "<frozen importlib._bootstrap>", line 488, in _call_with_frames_removed
  File "C:\_Tmp\Python\saf\articulos\urls.py", line 3, in <module>
    from .views import agregar_parametro, listar_parametros, prueba_formulario
ImportError: cannot import name 'prueba_formulario' from 'articulos.views' (C:\_Tmp\Python\saf\articulos\views.py)
^C